<?xml version="1.0"?>
<robot xmlns:xacro="http://www.ros.org/wiki/xacro" name="ABot">

  <!--<link name="base_footprint">
   </link>

  <joint name="base_footprint_joint" type="fixed">
     <parent link="base_footprint"/>
     <child link="base_link"/>
     <origin xyz="0.00 0.00 0.1" rpy="0.0 0.0 0.0"/>
   </joint>-->

  <link name="base_link">
  <inertial>
    <origin xyz="0 0 0.125" />
    <mass value="5" />
    <inertia  ixx="0.1" ixy="0.0"  ixz="0.0"  iyy="0.1"  iyz="0.0"  izz="0.1" />
  </inertial>
  <visual>
    <origin xyz="0 0 0.125"/>
    <geometry>
      <box size="0.4 0.2 0.1" />
    </geometry>
  </visual>
  <collision>
    <origin xyz="0 0 0.125"/>
    <geometry>
      <box size="0.4 0.2 0.1" />
    </geometry>
  </collision>
  </link>

   <link name="box">
  <inertial>
    <origin xyz="0 0 0" />
    <mass value="5" />
    <inertia  ixx="0.1" ixy="0.0"  ixz="0.0"  iyy="0.1"  iyz="0.0"  izz="0.1" />
  </inertial>
  <visual>
    <origin xyz="0 0 0"/>
    <geometry>
      <box size="0.3 0.2 0.1" />
    </geometry>
  </visual>
  <collision>
    <origin xyz="0 0 0"/>
    <geometry>
      <box size="0.3 0.2 0.1" />
    </geometry>
  </collision>
  </link>

  <joint name="base_link_box" type="fixed">
    <parent link="base_link"/>
    <child link="box"/>
    <axis xyz="0 0 0"/>
    <origin xyz="-0.05 0 0.225"/>
  </joint>

  <gazebo reference="base_link">
    <material>Gazebo/Blue</material>
  </gazebo>

  <link name="right_wheel">
  <inertial>
    <origin rpy="1.5707963267948966 0 0" xyz="0 0 0" />
    <mass value="0.1" />
    <inertia  ixx="0.01" ixy="0.0"  ixz="0.0"  iyy="0.01"  iyz="0.0"  izz="0.01" />
  </inertial>
  <visual>
    <origin rpy="1.5707963267948966 0 0" xyz="0 0 0"/>
    <geometry>
      <cylinder length="0.05" radius="0.075"/>
    </geometry>
  </visual>
  <collision>
    <origin rpy="1.5707963267948966 0 0" xyz="0 0 0"/>
    <geometry>
      <cylinder length="0.05" radius="0.075"/>
    </geometry>
  </collision>
  </link>

  <gazebo reference="right_wheel">
    <material>Gazebo/Black</material>
  </gazebo>

  <joint name="base_link_right_wheel" type="continuous">
    <parent link="base_link"/>
    <child link="right_wheel"/>
    <axis xyz="0 1 0"/>
    <origin xyz="0.1 -0.15 0.075"/>
  </joint>

  <transmission name="T_base_link_right_wheel">
    <type>transmission_interface/SimpleTransmission</type>
    <actuator name="motor_1">
      <mechanicalReduction>1</mechanicalReduction>
      <hardwareInterface>hardware_interface/VelocityJointInterface</hardwareInterface>
    </actuator>
    <joint name="base_link_right_wheel">
      <hardwareInterface>hardware_interface/VelocityJointInterface</hardwareInterface>
    </joint>
  </transmission>

  <link name="left_wheel">
  <inertial>
    <origin rpy="1.5707963267948966 0 0" xyz="0 0 0" />
    <mass value="0.1" />
    <inertia  ixx="0.01" ixy="0.0"  ixz="0.0"  iyy="0.01"  iyz="0.0"  izz="0.01" />
  </inertial>
  <visual>
    <origin rpy="1.5707963267948966 0 0" xyz="0 0 0"/>
    <geometry>
      <cylinder length="0.05" radius="0.075"/>
    </geometry>
  </visual>
  <collision>
    <origin rpy="1.5707963267948966 0 0" xyz="0 0 0"/>
    <geometry>
      <cylinder length="0.05" radius="0.075"/>
    </geometry>
  </collision>
  </link>

  <gazebo reference="left_wheel">
    <material>Gazebo/Black</material>
  </gazebo>

  <joint name="base_link_left_wheel" type="continuous">
    <parent link="base_link"/>
    <child link="left_wheel"/>
    <axis xyz="0 1 0"/>
    <origin xyz="0.1 0.15 0.075"/>
  </joint>

  <transmission name="T_base_link_left_wheel">
    <type>transmission_interface/SimpleTransmission</type>
    <actuator name="motor_2">
      <mechanicalReduction>1</mechanicalReduction>
      <hardwareInterface>hardware_interface/VelocityJointInterface</hardwareInterface>
    </actuator>
    <joint name="base_link_left_wheel">
      <hardwareInterface>hardware_interface/VelocityJointInterface</hardwareInterface>
    </joint>
  </transmission>

  <link name="back_wheel">
  <inertial>
    <origin rpy="1.5707963267948966 0 0" xyz="0 0 0" />
    <mass value="0.1" />
    <inertia  ixx="0.01" ixy="0.0"  ixz="0.0"  iyy="0.01"  iyz="0.0"  izz="0.01" />
  </inertial>
  <visual>
    <origin rpy="1.5707963267948966 0 0" xyz="0 0 0"/>
    <geometry>
      <sphere length="0.1" radius="0.025"/>
    </geometry>
  </visual>
  <collision>
    <origin rpy="1.5707963267948966 0 0" xyz="0 0 0"/>
    <geometry>
      <sphere length="0.1" radius="0.025"/>
    </geometry>
  </collision>
      <surface>
        <friction>
          <ode>
            <mu>0.000001</mu>
            <mu2>0.000001</mu2>
          </ode>
        </friction>
      </surface>
  </link>

   <joint name="base_link_back_wheel" type="fixed">
    <parent link="base_link"/>
    <child link="back_wheel"/>
    <axis xyz="0 1 1"/>
    <origin xyz="-0.15 0 0.025"/>
  </joint>

  <gazebo reference="back_wheel">
    <material>Gazebo/White</material>
    <mu1>0.000001</mu1>
    <mu2>0.000001</mu2>
  </gazebo>

 

<link name="camera_link">
    <collision>
      <origin xyz="0 0 0" rpy="0 0 0"/>
      <geometry>
    <box size="0.01 0.01 0.01"/>
      </geometry>
    </collision>

    <visual>
      <origin xyz="0 0 0" rpy="0 0 0"/>
      <geometry>
    <box size="0.01 0.01 0.01"/>
      </geometry>
      <material name="red"/>
    </visual>

    <inertial>
      <mass value="1e-5" />
      <origin xyz="0 0 0" rpy="0 0 0"/>
      <inertia ixx="1e-6" ixy="0" ixz="0" iyy="1e-6" iyz="0" izz="1e-6" />
    </inertial>
  </link>

<joint name="hokuyo_joint" type="fixed">
    <axis xyz="0 1 0" />
    <origin xyz="0.15 0 0.2" rpy="0 0 0"/>
    <parent link="base_link"/>
    <child link="hokuyo_link"/>
  </joint>

  <!-- Hokuyo Laser -->
  <link name="hokuyo_link">
    <collision>
      <origin xyz="0 0 0" rpy="0 0 0"/>
      <geometry>
    <box size="0.1 0.1 0.1"/>
      </geometry>
    </collision>

    <visual>
      <origin xyz="0 0 0" rpy="0 0 0"/>
      <geometry>
        <mesh filename="package://gazebo_demo/urdf/hokuyo.dae"/>
      </geometry>
    </visual>

    <inertial>
      <mass value="1e-5" />
      <origin xyz="0 0 0" rpy="0 0 0"/>
      <inertia ixx="1e-6" ixy="0" ixz="0" iyy="1e-6" iyz="0" izz="1e-6" />
    </inertial>
  </link>

<joint name="camera_joint" type="fixed">
    <axis xyz="0 0 0" />
    <origin xyz="0.2 0 0.25" rpy="0 0 0"/>
    <parent link="base_link"/>
    <child link="camera_link"/>
  </joint>

<gazebo reference="camera_link">
    <sensor type="camera" name="camera">
      <update_rate>30.0</update_rate>
      <camera name="head">
        <horizontal_fov>1.3962634</horizontal_fov>
        <image>
          <width>640</width>
          <height>480</height>
          <format>R8G8B8</format>
        </image>
        <clip>
          <near>0.02</near>
          <far>300</far>
        </clip>
        <noise>
          <type>gaussian</type>
          <!-- Noise is sampled independently per pixel on each frame.
               That pixel's noise value is added to each of its color
               channels, which at that point lie in the range [0,1]. -->
          <mean>0.0</mean>
          <stddev>0.007</stddev>
        </noise>
      </camera>
      <plugin name="camera_controller" filename="libgazebo_ros_camera.so">
        <alwaysOn>true</alwaysOn>
        <updateRate>30.0</updateRate>
        <cameraName>/camera</cameraName>
        <imageTopicName>image_raw</imageTopicName>
        <cameraInfoTopicName>camera_info</cameraInfoTopicName>
        <frameName>camera_link</frameName>
        <hackBaseline>0.07</hackBaseline>
        <distortionK1>0.0</distortionK1>
        <distortionK2>0.0</distortionK2>
        <distortionK3>0.0</distortionK3>
        <distortionT1>0.0</distortionT1>
        <distortionT2>0.0</distortionT2>
      </plugin>
    </sensor>
  </gazebo>

 

<gazebo>
  <plugin name="differential_drive_controller" filename="libgazebo_ros_diff_drive.so">
    <alwaysOn>true</alwaysOn>
    <updateRate>10</updateRate>
    <leftJoint>base_link_left_wheel</leftJoint>
    <rightJoint>base_link_right_wheel</rightJoint>
    <wheelSeparation>0.35</wheelSeparation>
    <wheelDiameter>0.15</wheelDiameter>
    <torque>1.41</torque>
    <commandTopic>cmd_vel</commandTopic>
    <odometryTopic>odom</odometryTopic>
    <odometryFrame>odom</odometryFrame>
    <robotBaseFrame>base_link</robotBaseFrame>
    <publishWheelJointState>true</publishWheelJointState>
    <enable_odom_tf>false</enable_odom_tf>
  </plugin>
</gazebo>

 <gazebo reference="hokuyo_link">
    <sensor type="gpu_ray" name="head_hokuyo_sensor">
      <pose>0 0 0 0 0 0</pose>
      <visualize>true</visualize>
      <update_rate>10</update_rate>
      <ray>
        <scan>
          <horizontal>
            <samples>720</samples>
            <resolution>1</resolution>
            <min_angle>-1.570796</min_angle>
            <max_angle>1.570796</max_angle>
          </horizontal>
        </scan>
        <range>
          <min>0.10</min>
          <max>20.0</max>
          <resolution>0.01</resolution>
        </range>
        <noise>
          <type>gaussian</type>
          <!-- Noise parameters based on published spec for Hokuyo laser
               achieving "+-30mm" accuracy at range < 10m.  A mean of 0.0m and
               stddev of 0.01m will put 99.7% of samples within 0.03m of the true
               reading. -->
          <mean>0.0</mean>
          <stddev>0.01</stddev>
        </noise>
      </ray>
      <plugin name="gazebo_ros_head_hokuyo_controller" filename="libgazebo_ros_gpu_laser.so">
        <topicName>scan</topicName>
        <frameName>hokuyo_link</frameName>
      </plugin>
    </sensor>
  </gazebo>
  
  <xacro:property name="hokuyo_link" value="0.05" />

  <xacro:property name="camera_link" value="0.05" />

</robot>
